<?xml version="1.0" ?>
<!-- =================================================================================== -->
<!-- |    This document was autogenerated by xacro from tx60l.xacro                    | -->
<!-- |    EDITING THIS FILE BY HAND IS NOT RECOMMENDED                                 | -->
<!-- =================================================================================== -->
<robot name="staubli_tx260l" xmlns:xacro="http://ros.org/wiki/xacro">
  <!-- colours based on RAL values supplied by Staubli -->
  <!-- all RAL colours converted using http://www.visual-graphics.de/en/customer-care/ral-colours -->
  <!-- default colours for robots -->
  <!-- links -->
  <link name="base_link">
    <visual>
      <origin rpy="0 0 0" xyz="0 0 0"/>
      <geometry>
        <mesh filename="package://staubli_tx260l_support/meshes/tx60l/visual/base_link.stl"/>
      </geometry>
      <material name="">
        <color rgba="1.0 0.607843137255 0.0 1.0"/>
      </material>
    </visual>
    <collision>
      <origin rpy="0 0 0" xyz="0 0 0"/>
      <geometry>
        <mesh filename="package://staubli_tx260l_support/meshes/tx60l/collision/base_link.stl"/>
      </geometry>
    </collision>
    <inertial>
      <mass value="5.76415"/>
      <origin rpy="0.0 0.0 0.0" xyz="-0.010284 -0.000676 0.087340"/>
      <inertia ixx="0.000025" ixy="-0.000001" ixz="-0.000002" iyy="0.000034" iyz="-0.0000001" izz="0.000029"/>
    </inertial>
  </link>
  <link name="link_1">
    <visual>
      <origin rpy="0 0 0" xyz="0 0 0"/>
      <geometry>
        <mesh filename="package://staubli_tx260l_support/meshes/tx60l/visual/link_1.stl"/>
      </geometry>
      <material name="">
        <color rgba="1.0 0.607843137255 0.0 1.0"/>
      </material>
    </visual>
    <collision>
      <origin rpy="0 0 0" xyz="0 0 0"/>
      <geometry>
        <mesh filename="package://staubli_tx260l_support/meshes/tx60l/collision/link_1.stl"/>
      </geometry>
    </collision>
    <inertial>
      <mass value="7.769025"/>
      <origin rpy="0.0 0.0 0.0" xyz="-0.000234 0.023187 0.322578"/>
      <inertia ixx="0.000059" ixy="-0.0000001" ixz="-0.0000005839" iyy="0.0001436040" iyz="0.0000040196" izz="0.0000118231"/>
    </inertial>
  </link>
  <link name="link_2">
    <visual>
      <origin rpy="0 0 0" xyz="0 0 0"/>
      <geometry>
        <mesh filename="package://staubli_tx260l_support/meshes/tx60l/visual/link_2.stl"/>
      </geometry>
      <material name="">
        <color rgba="1.0 0.607843137255 0.0 1.0"/>
      </material>
    </visual>
    <collision>
      <origin rpy="0 0 0" xyz="0 0 0"/>
      <geometry>
        <mesh filename="package://staubli_tx260l_support/meshes/tx60l/collision/link_2.stl"/>
      </geometry>
    </collision>
    <inertial>
      <mass value="14.350897"/>
      <origin rpy="0.0 0.0 0.0" xyz="0.002379421 0.041907421 0.170583237"/>
      <inertia ixx="0.000137" ixy="0.000000" ixz="-0.000001" iyy="0.000144" iyz="0.000004" izz="0.000012"/>
    </inertial>
  </link>
  <link name="link_3">
    <visual>
      <origin rpy="0 0 0" xyz="0 0 0"/>
      <geometry>
        <mesh filename="package://staubli_tx260l_support/meshes/tx60l/visual/link_3.stl"/>
      </geometry>
      <material name="">
        <color rgba="1.0 0.607843137255 0.0 1.0"/>
      </material>
    </visual>
    <collision>
      <origin rpy="0 0 0" xyz="0 0 0"/>
      <geometry>
        <mesh filename="package://staubli_tx260l_support/meshes/tx60l/collision/link_3.stl"/>
      </geometry>
    </collision>
    <inertial>
      <mass value="5.16"/>
      <origin rpy="0.0 0.0 0.0" xyz="-0.003889 0.019212 -0.007944"/>
      <inertia ixx="0.000030" ixy="-0.000001" ixz="-0.000000" iyy="0.000022" iyz="0.000001" izz="0.000020"/>
    </inertial>
  </link>
  <link name="link_4">
    <visual>
      <origin rpy="0 0 0" xyz="0 0 0"/>
      <geometry>
        <mesh filename="package://staubli_tx260l_support/meshes/tx60l/visual/link_4.stl"/>
      </geometry>
      <material name="">
        <color rgba="1.0 0.607843137255 0.0 1.0"/>
      </material>
    </visual>
    <collision>
      <origin rpy="0 0 0" xyz="0 0 0"/>
      <geometry>
        <mesh filename="package://staubli_tx260l_support/meshes/tx60l/collision/link_4.stl"/>
      </geometry>
    </collision>
    <inertial>
      <mass value="4.0287377"/>
      <origin rpy="0.0 0.0 0.0" xyz="-0.001208 -0.000000 0.287605"/>
      <inertia ixx="0.000042" ixy="-0.000000" ixz="0.000001" iyy="0.000041" iyz="-0.000000" izz="0.000007"/>
    </inertial>
  </link>
  <link name="link_5">
    <visual>
      <origin rpy="0 0 0" xyz="0 0 0"/>
      <geometry>
        <mesh filename="package://staubli_tx260l_support/meshes/tx60l/visual/link_5.stl"/>
      </geometry>
      <material name="">
        <color rgba="0.529411764706 0.521568627451 0.505882352941 1.0"/>
      </material>
    </visual>
    <collision>
      <origin rpy="0 0 0" xyz="0 0 0"/>
      <geometry>
        <mesh filename="package://staubli_tx260l_support/meshes/tx60l/collision/link_5.stl"/>
      </geometry>
    </collision>
    <inertial>
      <mass value="0.123625"/>
      <origin rpy="0.0 0.0 0.0" xyz="0.000190 0.000001 0.015244"/>
      <inertia ixx="0.000000" ixy="0.000000" ixz="0.000000" iyy="0.000000" iyz="0.000000" izz="0.000000"/>
    </inertial>
  </link>
  <link name="link_6">
    <visual>
      <origin rpy="0 0 0" xyz="0 0 0"/>
      <geometry>
        <mesh filename="package://staubli_tx260l_support/meshes/tx60l/visual/link_6.stl"/>
      </geometry>
      <material name="">
        <color rgba="0.529411764706 0.521568627451 0.505882352941 1.0"/>
      </material>
    </visual>
    <collision>
      <origin rpy="0 0 0" xyz="0 0 0"/>
      <geometry>
        <mesh filename="package://staubli_tx260l_support/meshes/tx60l/collision/link_6.stl"/>
      </geometry>
    </collision>
    <inertial>
      <mass value="0.123625"/>
      <origin rpy="0.0 0.0 0.0" xyz="-0.000195 -0.000000 -0.006636"/>
      <inertia ixx="0.000000" ixy="-0.000000" ixz="0.000000" iyy="0.000000" iyz="0.000000" izz="0.000000"/>
    </inertial>
  </link>
  <link name="tool0"/>
  <!-- joints -->
  <joint name="joint_1" type="revolute">
    <origin rpy="0 0 0" xyz="0 0 0"/>
    <parent link="base_link"/>
    <child link="link_1"/>
    <axis xyz="0 0 1"/>
    <!-- from Staubli instruction manual:
      (1) effort limit = 318 Nm if floor mounted
      (2) effort limit = 111 Nm if wall mounted -->
    <limit effort="318.0" lower="-3.14159265" upper="3.14159265" velocity="7.592"/>
    <dynamics damping="0.0" friction="0.0"/>
  </joint>
  <joint name="joint_2" type="revolute">
    <origin rpy="0 0 0" xyz="0.0 0.130 0.375"/>
    <parent link="link_1"/>
    <child link="link_2"/>
    <axis xyz="0 1 0"/>
    <limit effort="130.0" lower="-2.22529" upper="2.22529" velocity="6.719"/>
    <dynamics damping="0.0" friction="0.0"/>
  </joint>
  <joint name="joint_3" type="revolute">
    <origin rpy="0 0 0" xyz="0 -0.110 0.400"/>
    <parent link="link_2"/>
    <child link="link_3"/>
    <axis xyz="0 1 0"/>
    <limit effort="65.0" lower="-2.48709" upper="2.48709" velocity="8.726"/>
    <dynamics damping="0.0" friction="0.0"/>
  </joint>
  <joint name="joint_4" type="revolute">
    <origin rpy="0 0 0" xyz="0 0 0"/>
    <parent link="link_3"/>
    <child link="link_4"/>
    <axis xyz="0 0 1"/>
    <limit effort="34.0" lower="-4.712389" upper="4.712389" velocity="17.366"/>
    <dynamics damping="0.0" friction="0.0"/>
  </joint>
  <joint name="joint_5" type="revolute">
    <origin rpy="0 0 0" xyz="0 0 0.450"/>
    <parent link="link_4"/>
    <child link="link_5"/>
    <axis xyz="0 1 0"/>
    <limit effort="29.0" lower="-2.138028" upper="2.3125612" velocity="18.587"/>
    <dynamics damping="0.0" friction="0.0"/>
  </joint>
  <joint name="joint_6" type="revolute">
    <origin rpy="0 0 0" xyz="0 0 0.070"/>
    <parent link="link_5"/>
    <child link="link_6"/>
    <axis xyz="0 0 1"/>
    <limit effort="11.0" lower="-4.712389" upper="4.712389" velocity="25.220"/>
    <dynamics damping="0.0" friction="0.0"/>
  </joint>
  <joint name="joint_6-tool0" type="fixed">
    <parent link="link_6"/>
    <child link="tool0"/>
    <origin rpy="0 0 0" xyz="0 0 0"/>
  </joint>
</robot>

